Workbook
Name MY_FUNCTION1: LAMBDA(COUNTIF(#REF!,{"D2"; "D2a"; "D2p"})+COUNTIF(#REF!,{"D2"; "D2a"; "D2p"}))

Sheet BHTH
A1: https://infoinspired.com/google-docs/spreadsheet/learn-query-function-with-examples-in-google-sheets/
A2: Block 9 | F2: M | G2: T | H2: W | I2: Th | J2: F | K2: Sa | L2: Su | M2: M | N2: T | O2: W | P2: Th | Q2: F | R2: Sa | S2: Su | T2: M | U2: T | V2: W | W2: Th | X2: F | Y2: Sa | Z2: Su | AA2: M | AB2: T | AC2: W | AD2: Th | AE2: F | AF2: Sa | AG2: Su
A3: 02/09/26-03/08/26 | F3: 9 | G3: 10 | H3: 11 | I3: 12 | J3: 13 | K3: 14 | L3: 15 | M3: 16 | N3: 17 | O3: 18 | P3: 19 | Q3: 20 | R3: 21 | S3: 22 | T3: 23 | U3: 24 | V3: 25 | W3: 26 | X3: 27 | Y3: 28 | Z3: 1 | AA3: 2 | AB3: 3 | AC3: 4 | AD3: 5 | AE3: 6 | AF3: 7 | AG3: 8
A4: OSR | B4: Amion ID | C4: Before | D4: Block | E4: After | F4: =countif(F52:F68, "X") -> 0 | G4: =countif(G52:G68, "X") -> 0 | H4: =countif(H52:H68, "X") -> 0 | I4: =countif(I52:I68, "X") -> 0 | J4: =countif(J52:J68, "X") -> 0 | K4: =countif(K52:K68, "X") -> 0 | L4: =countif(L52:L68, "X") -> 0 | M4: =countif(M52:M68, "X") -> 0 | ... AA4: =countif(AA52:AA68, "X") -> 0 | AB4: =countif(AB52:AB67, "X") -> 0 | AC4: =countif(AC52:AC68, "X") -> 0 | AD4: =countif(AD52:AD68, "X") -> 0 | AE4: =countif(AE52:AE68, "X") -> 0 | AF4: =countif(AF52:AF68, "X") -> 0 | AG4: =countif(AG52:AG68, "X") -> 0
A5: Phillip Cohen (Med) | B5: PC | F5: n2b
A6: Elizabeth Flagg (Med) | B6: EF | G6: d2b
A7: Abhishek Bhattacharya (Med) | B7: ABh | F7: d2b | G7: d4
A8: Tyler Warner (Ortho) | F8: n2a | G8: n2a | J8: d1 | K8: d2 | L8: d2 | M8: d1 | N8: d3 | O8: d4 | Q8: d5 | R8: n2 | S8: n2 | T8: n2b | U8: n2a | V8: n2a | W8: n2a | Z8: d3 | AA8: d3 | AB8: d2b
A9: Yonathan Daniel (Med) | B9: YD | H9: n2a | I9: n2a | J9: n2a | K9: n2 | L9: n2 | P9: d2b | Q9: d2b | R9: d2 | S9: d1
A10: Jeremy Perrelle (Med) | B10: JPl | I10: d5 | J10: n2b | K10: n2 | L10: n2 | M10: n2b | N10: n2b | P10: d4 | S10: d2 | T10: d5
A11: Colby Smith (Med) | B11: CS | I11: d2b | J11: d5 | K11: d1 | M11: n2a | N11: n2a | O11: n2a | P11: n2a | Q11: n2a | T11: d4a
A12: Mariela Trejo (Med) | B12: MTr | H12: d5 | J12: d2b | M12: d2b | N12: d2b | O12: n2b | P12: n2b | Q12: n2b | R12: n2 | S12: n2
A13: Geoffrey Cloud (Med) | B13: GC | V13: d4 | W13: d5 | X13: d1 | Y13: d2 | AA13: n2a | AB13: n2a | AC13: n2b | AD13: n2b | AF13: d2
A14: Daniel Grubman (Med) | B14: DG | W14: d3 | X14: n2a | Y14: n2 | Z14: n2 | AA14: n2b | AC14: d4 | AD14: d5 | AE14: d4 | AG14: d2
A15: Katharine Martin (Med) | B15: KMa | W15: d4 | X15: d5 | Y15: d3 | AB15: d4 | AC15: n2a | AD15: n2a | AE15: n2a | AF15: n2 | AG15: n2
A16: Carolyn Wilson (Med) | B16: CWi | V16: d5 | W16: d2b | X16: d2b | Y16: d1 | Z16: d2 | AA16: d2b | AE16: n2b | AF16: n2 | AG16: n2
A17: Nimi Patel (Psych) | B17: NP | T17: d2b | U17: n2b | V17: n2b | W17: n2b | X17: n2b | Y17: n2 | Z17: n2 | AD17: d2b | AE17: d2b
A18: PGY-1 | B18: Amion ID | C18: Before | D18: Block | E18: After
A19: Brian Morrissey | B19: BMo | C19: =VLOOKUP(A19, 'PGY1'!$A$3:$AA$20, 17, FALSE) -> AnUS | D19: =concatenate(vlookup(A19,'PGY1'!$A$3:$AA$20, 18, false), " / ", vlookup(A19,'PGY1'!$A$3:$AA$20, 19, false)) -> BH / J | E19: =VLOOKUP(A19, 'PGY1'!$A$3:$AA$20, 20, FALSE) -> BK | F19: k2b | G19: k2b | I19: k2a | J19: k2a | N19: k2b | P19: k2b | Q19: t1n | R19: t1n | S19: t1n
A20: Luis Sanchez | B20: LSa | C20: =VLOOKUP(A20, 'PGY1'!$A$3:$AA$20, 17, FALSE) -> BH | D20: =concatenate(vlookup(A20,'PGY1'!$A$3:$AA$20, 18, false), " / ", vlookup(A20,'PGY1'!$A$3:$AA$20, 19, false)) -> BH / NICU | E20: =VLOOKUP(A20, 'PGY1'!$A$3:$AA$20, 20, FALSE) -> AnUS | F20: d1 | G20: n2b | H20: n2b | I20: n2b | K20: k2a | L20: k2a | M20: k2b | N20: d4 | O20: d5
A21: Jude Luke | B21: JL | C21: =VLOOKUP(A21, 'PGY1'!$A$3:$AA$20, 17, FALSE) -> J | D21: =concatenate(vlookup(A21,'PGY1'!$A$3:$AA$20, 18, false), " / ", vlookup(A21,'PGY1'!$A$3:$AA$20, 19, false)) -> TH / TH | E21: =VLOOKUP(A21, 'PGY1'!$A$3:$AA$20, 20, FALSE) -> SICU | F21: t1n | G21: t1n | H21: t1n | I21: t1n | K21: th1a | L21: th1a | M21: k2a | N21: k2a | P21: k2a | Q21: k2a | U21: k2b | W21: k2a | Y21: th1a | Z21: th1a | AB21: n2b | AC21: t1n | AD21: t1n | AE21: t1n
A22: Soley Olafsson | B22: SO | C22: =VLOOKUP(A22, 'PGY1'!$A$3:$AA$20, 17, FALSE) -> M | D22: =concatenate(vlookup(A22,'PGY1'!$A$3:$AA$20, 18, false), " / ", vlookup(A22,'PGY1'!$A$3:$AA$20, 19, false)) -> TH / BH | E22: =VLOOKUP(A22, 'PGY1'!$A$3:$AA$20, 20, FALSE) -> V | F22: k2a | G22: k2a | I22: k2b | J22: t1n | K22: t1n | L22: t1n | O22: wc | P22: d1 | Q22: d3 | R22: d1 | S22: d3 | T22: n1 | U22: n3 | V22: n1 | W22: n3 | AA22: k2b | AB22: d1 | AD22: d1
A23: Ruby Chung | B23: RCu | C23: =VLOOKUP(A23, 'PGY1'!$A$3:$AA$20, 17, FALSE) -> TH | D23: =concatenate(vlookup(A23,'PGY1'!$A$3:$AA$20, 18, false), " / ", vlookup(A23,'PGY1'!$A$3:$AA$20, 19, false)) -> PSY / BH | E23: =VLOOKUP(A23, 'PGY1'!$A$3:$AA$20, 20, FALSE) -> TH | U23: d2b | V23: d2b | W23: d2a | X23: d4 | AA23: d4 | AD23: d4 | AE23: n1 | AF23: n3 | AG23: n1
A24: Libby Ho | B24: LH | C24: =VLOOKUP(A24, 'PGY1'!$A$3:$AA$20, 17, FALSE) -> BH | D24: =concatenate(vlookup(A24,'PGY1'!$A$3:$AA$20, 18, false), " / ", vlookup(A24,'PGY1'!$A$3:$AA$20, 19, false)) -> BK / TH | E24: =VLOOKUP(A24, 'PGY1'!$A$3:$AA$20, 20, FALSE) -> MICU | T24: n2a | U24: t1n | V24: t1n | W24: n1 | X24: t1n | AB24: k2a | AE24: k2b | AF24: t1n | AG24: t1n
A25: Leia Kessler | B25: LK | C25: =VLOOKUP(A25, 'PGY1'!$A$3:$AA$20, 17, FALSE) -> TH | D25: =concatenate(vlookup(A25,'PGY1'!$A$3:$AA$20, 18, false), " / ", vlookup(A25,'PGY1'!$A$3:$AA$20, 19, false)) -> PedB / BH | E25: =VLOOKUP(A25, 'PGY1'!$A$3:$AA$20, 20, FALSE) -> BK | T25: n3 | U25: n1 | V25: n3 | W25: t1n | AA25: d4a | AD25: k2a | AE25: d1 | AF25: d1 | AG25: d3
A26: Gabrielle Ramirez | B26: GRa | C26: =VLOOKUP(A26, 'PGY1'!$A$3:$AA$20, 17, FALSE) -> MICU | D26: =concatenate(vlookup(A26,'PGY1'!$A$3:$AA$20, 18, false), " / ", vlookup(A26,'PGY1'!$A$3:$AA$20, 19, false)) -> BK / TH | E26: =VLOOKUP(A26, 'PGY1'!$A$3:$AA$20, 20, FALSE) -> T | T26: k2a | U26: k2a | V26: wc | W26: k2b | X26: k2b | Y26: t1n | Z26: t1n | AA26: t1n | AB26: t1n | AD26: k2b
A27: PGY-2 | B27: Amion ID | C27: Before | D27: Block | E27: After
A28: Anas Maqsood | B28: AM | C28: =VLOOKUP(A28, 'PGY2'!$A$3:$AA$20, 17, FALSE) -> Ob | D28: =concatenate(vlookup(A28,'PGY2'!$A$3:$AA$20, 18, false), " / ", vlookup(A28,'PGY2'!$A$3:$AA$20, 19, false)) -> BH/TH / PedT | E28: =VLOOKUP(A28, 'PGY2'!$A$3:$AA$20, 20, FALSE) -> BH/TH | F28: d2a | G28: d1 | H28: wc | J28: k2b | M28: t1n | N28: n1 | O28: n3 | P28: n1 | R28: d3 | S28: d2
A29: Edom Girma | B29: EGi | C29: =VLOOKUP(A29, 'PGY2'!$A$3:$AA$20, 17, FALSE) -> Ortho | D29: =concatenate(vlookup(A29,'PGY2'!$A$3:$AA$20, 18, false), " / ", vlookup(A29,'PGY2'!$A$3:$AA$20, 19, false)) -> BH/TH / AnUS | E29: =VLOOKUP(A29, 'PGY2'!$A$3:$AA$20, 20, FALSE) -> BH/TH | F29: n1 | G29: n3 | H29: n1 | I29: n3 | L29: d1 | M29: d2a | Q29: d1 | R29: d2 | S29: k2a
A30: Jacqueline Penn | B30: JPe | C30: =VLOOKUP(A30, 'PGY2'!$A$3:$AA$20, 17, FALSE) -> Ortho | D30: =concatenate(vlookup(A30,'PGY2'!$A$3:$AA$20, 18, false), " / ", vlookup(A30,'PGY2'!$A$3:$AA$20, 19, false)) -> BH/TH / PedB | E30: =VLOOKUP(A30, 'PGY2'!$A$3:$AA$20, 20, FALSE) -> Ob | F30: n3 | G30: n1 | H30: n3 | I30: n1 | K30: d2 | L30: d2 | M30: d5 | N30: d1 | Q30: d2a
A31: Christopher Connolly | B31: CC | C31: =VLOOKUP(A31, 'PGY2'!$A$3:$AA$20, 17, FALSE) -> PedB | D31: =concatenate(vlookup(A31,'PGY2'!$A$3:$AA$20, 18, false), " / ", vlookup(A31,'PGY2'!$A$3:$AA$20, 19, false)) -> BH/TH / BH/TH | E31: =VLOOKUP(A31, 'PGY2'!$A$3:$AA$20, 20, FALSE) -> BH/TH | F31: d4 | G31: d5 | I31: d4 | J31: n1 | K31: n3 | L31: n1 | M31: n3 | O31: d2b | P31: d5 | Q31: d4 | T31: d2a | U31: d4a | W31: R | X31: n1 | Y31: n3 | Z31: n1 | AB31: d5 | AC31: d2b | AD31: d2a
A32: Eilish Moogan | B32: EMo | C32: =VLOOKUP(A32, 'PGY2'!$A$3:$AA$20, 17, FALSE) -> BK | D32: =concatenate(vlookup(A32,'PGY2'!$A$3:$AA$20, 18, false), " / ", vlookup(A32,'PGY2'!$A$3:$AA$20, 19, false)) -> BH/TH / BH/TH | E32: =VLOOKUP(A32, 'PGY2'!$A$3:$AA$20, 20, FALSE) -> Ortho | F32: d4a | G32: d2a | I32: d3 | J32: n3 | K32: n1 | L32: n3 | M32: n1 | N32: t1n | P32: d2a | Q32: k2b | T32: d1 | U32: d3 | V32: P | W32: E | AA32: d5 | AB32: k2b | AC32: n1 | AE32: d2a | AF32: d2 | AG32: d2
A33: Jason Martinez | B33: JMr | C33: =VLOOKUP(A33, 'PGY2'!$A$3:$AA$20, 17, FALSE) -> BH/TH | D33: =concatenate(vlookup(A33,'PGY2'!$A$3:$AA$20, 18, false), " / ", vlookup(A33,'PGY2'!$A$3:$AA$20, 19, false)) -> BH/TH / BH/TH | E33: =VLOOKUP(A33, 'PGY2'!$A$3:$AA$20, 20, FALSE) -> EMS | F33: d3 | G33: d4a | I33: d2a | J33: d2a | K33: d3 | M33: d3 | N33: d2a | O33: t1n | P33: n3 | Q33: n1 | R33: n3 | S33: n1 | T33: t1n | V33: G | W33: T | X33: d3 | AA33: d2a | AB33: d3 | AC33: d5 | AE33: k2a
A34: Paul Capobianco | B34: PCa | C34: =VLOOKUP(A34, 'PGY2'!$A$3:$AA$20, 17, FALSE) -> J | D34: =concatenate(vlookup(A34,'PGY2'!$A$3:$AA$20, 18, false), " / ", vlookup(A34,'PGY2'!$A$3:$AA$20, 19, false)) -> BH/TH / BH/TH | E34: =VLOOKUP(A34, 'PGY2'!$A$3:$AA$20, 20, FALSE) -> V | F34: d5 | G34: d3 | H34: d2b | I34: d1 | J34: d3 | M34: d4 | N34: n3 | O34: n1 | P34: t1n | Q34: n3 | R34: n1 | S34: n3 | U34: d1 | V34: Y | W34: R | Y34: d2 | Z34: d2 | AA34: d1 | AB34: d2a | AE34: d3
A35: JiMin Ko | B35: JK | C35: =VLOOKUP(A35, 'PGY2'!$A$3:$AA$20, 17, FALSE) -> BH/TH | D35: =concatenate(vlookup(A35,'PGY2'!$A$3:$AA$20, 18, false), " / ", vlookup(A35,'PGY2'!$A$3:$AA$20, 19, false)) -> EMS / BH/TH | E35: =VLOOKUP(A35, 'PGY2'!$A$3:$AA$20, 20, FALSE) -> BH/TH | T35: d3 | U35: d2a | V35: 2 | W35: E | X35: k2a | AA35: k2a | AB35: d4a | AC35: wc | AD35: n3 | AE35: n3 | AF35: n1 | AG35: n3
A36: Lauren Chung | B36: LCh | C36: =VLOOKUP(A36, 'PGY2'!$A$3:$AA$20, 17, FALSE) -> BH/TH | D36: =concatenate(vlookup(A36,'PGY2'!$A$3:$AA$20, 18, false), " / ", vlookup(A36,'PGY2'!$A$3:$AA$20, 19, false)) -> J / BH/TH | E36: =VLOOKUP(A36, 'PGY2'!$A$3:$AA$20, 20, FALSE) -> CCU | T36: d4 | U36: d5 | W36: A | X36: d2a | AA36: n3 | AB36: n1 | AC36: n3 | AD36: n1 | AF36: d3 | AG36: d1
A37: Nicholas Friedman | B37: NFr | C37: =VLOOKUP(A37, 'PGY2'!$A$3:$AA$20, 17, FALSE) -> V | D37: =concatenate(vlookup(A37,'PGY2'!$A$3:$AA$20, 18, false), " / ", vlookup(A37,'PGY2'!$A$3:$AA$20, 19, false)) -> PedB / BH/TH | E37: =VLOOKUP(A37, 'PGY2'!$A$3:$AA$20, 20, FALSE) -> BH/TH | T37: k2b | U37: d4 | W37: T | X37: n3 | Y37: n1 | Z37: n3 | AA37: n1 | AB37: n3 | AD37: d3 | AE37: d5
A38: PGY-3 | B38: Amion ID | C38: Before | D38: Block | E38: After | F38: =COUNTIF(F$39:F$68,"N") -> 0 | G38: =COUNTIF(G$39:G$68,"N") -> 0 | H38: =COUNTIF(H$39:H$68,"N") -> 0 | I38: =COUNTIF(I$39:I$68,"N") -> 0 | J38: =COUNTIF(J$39:J$68,"N") -> 0 | K38: =COUNTIF(K$39:K$68,"N") -> 0 | L38: =COUNTIF(L$39:L$68,"N") -> 0 | M38: =COUNTIF(M$39:M$68,"N") -> 0 | ... AA38: =COUNTIF(AA$39:AA$68,"N") -> 0 | AB38: =COUNTIF(AB$39:AB$67,"N") -> 0 | AC38: =COUNTIF(AC$39:AC$68,"N") -> 0 | AD38: =COUNTIF(AD$39:AD$68,"N") -> 0 | AE38: =COUNTIF(AE$39:AE$68,"N") -> 0 | AF38: =COUNTIF(AF$39:AF$68,"N") -> 0 | AG38: =COUNTIF(AG$39:AG$68,"N") -> 0
A39: Nir Lavi-Romer | B39: NLa | C39: =VLOOKUP(A39, 'PGY3'!$A$3:$AA$20, 17, FALSE) -> Elec | D39: =concatenate(vlookup(A39,'PGY3'!$A$3:$AA$20, 18, false), " / ", vlookup(A39,'PGY3'!$A$3:$AA$20, 19, false)) -> ED / Elec | E39: =VLOOKUP(A39, 'PGY3'!$A$3:$AA$20, 20, FALSE) -> MICU | F39: D1 | G39: D3 | H39: d4 | I39: D4 | J39: NF | K39: NF | L39: T1N | N39: BKA | O39: D1
A40: Spencer Evan | C40: MICU | D40: BKN / V | E40: ED | F40: BKA | G40: PB2 | I40: BK2 | J40: T1N | K40: T1N | L40: NF | O40: D3 | P40: BK9 | Q40: BKA | T40: PB2
...

Sheet PGY1
A1: 1 | B1: 1A | C1: 1B | D1: 2A | E1: 2B | F1: 3A | G1: 3B | H1: 4A | I1: 4B | J1: 5A | K1: 5B | L1: 6A | M1: 6B | N1: 7A | O1: 7B | P1: 8A | Q1: 8B | R1: 9A | S1: 9B | T1: 10A | U1: 10B | V1: 11A | W1: 11B | X1: 12A | Y1: 12B | Z1: 13A | AA1: 13B
B2: 44743 | C2: 45852 | D2: 45866 | E2: 45880 | F2: 45894 | G2: 45908 | H2: 45922 | I2: 45936 | J2: 45950 | K2: 45964 | L2: 45978 | M2: 45992 | N2: 46006 | O2: 46020 | P2: 45669 | Q2: 45683 | R2: 45697 | S2: 45711 | T2: 45725 | U2: 45739 | V2: 45753 | W2: 45767 | X2: 45781 | Y2: 45795 | Z2: 45809 | AA2: 45823
A3: Logan Brich | B3: O | C3: O | D3: T | E3: T | F3: SICU | G3: SICU | H3: PSY | I3: V | J3: TH | K3: AnUS | L3: MICU | M3: MICU | N3: BH | O3: BK | P3: V | Q3: NICU | R3: M | S3: M | T3: PedT | U3: BK | V3: TH | W3: J | X3: TH | Y3: TH | Z3: PedB | AA3: BH
A4: Caroline Brown | B4: O | C4: O | D4: SICU | E4: SICU | F4: T | G4: T | H4: TH | I4: PSY | J4: PedT | K4: TH | L4: J | M4: BK | N4: V | O4: BH | P4: MICU | Q4: MICU | R4: NICU | S4: AnUS | T4: TH | U4: TH | V4: M | W4: M | X4: BK | Y4: PedB | Z4: V | AA4: BH
A5: Ruby Chung | B5: O | C5: O | D5: T | E5: T | F5: NICU | G5: AnUS | H5: BK | I5: V | J5: SICU | K5: SICU | L5: TH | M5: TH | N5: MICU | O5: MICU | P5: BK | Q5: TH | R5: PSY | S5: BH | T5: TH | U5: PedT | V5: PedB | W5: V | X5: M | Y5: M | Z5: BH | AA5: J
A6: Jenna Ehlert | B6: O | C6: O | D6: TH | E6: BH | F6: MICU | G6: MICU | H6: BK | I6: V | J6: BH | K6: TH | L6: SICU | M6: SICU | N6: PedB | O6: BK | P6: TH | Q6: PSY | R6: T | S6: T | T6: NICU | U6: V | V6: TH | W6: PedT | X6: AnUS | Y6: J | Z6: M | AA6: M
A7: Grace Feng | B7: O | C7: O | D7: M | E7: M | F7: V | G7: TH | H7: T | I7: T | J7: J | K7: BH | L7: AnUS | M7: PedB | N7: V | O7: TH | P7: BK | Q7: BK | R7: MICU | S7: MICU | T7: PSY | U7: NICU | V7: BH | W7: TH | X7: SICU | Y7: SICU | Z7: PedT | AA7: TH
A8: Libby Ho | B8: O | C8: O | D8: SICU | E8: SICU | F8: M | G8: M | H8: T | I8: T | J8: PSY | K8: V | L8: BH | M8: PedT | N8: TH | O8: TH | P8: NICU | Q8: BH | R8: BK | S8: TH | T8: MICU | U8: MICU | V8: V | W8: TH | X8: J | Y8: AnUS | Z8: BK | AA8: PedB
A9: Leia Kessler | B9: O | C9: O | D9: M | E9: M | F9: V | G9: TH | H9: SICU | I9: SICU | J9: T | K9: T | L9: TH | M9: BH | N9: PedT | O9: NICU | P9: AnUS | Q9: TH | R9: PedB | S9: BH | T9: BK | U9: J | V9: MICU | W9: MICU | X9: PSY | Y9: V | Z9: BK | AA9: TH
A10: Phoebe Li | B10: O | C10: O | D10: BK | E10: NICU | F10: TH | G10: PedB | H10: BH | I10: V | J10: SICU | K10: SICU | L10: T | M10: T | N10: TH | O10: J | P10: BH | Q10: TH | R10: AnUS | S10: PSY | T10: M | U10: M | V10: V | W10: TH | X10: MICU | Y10: MICU | Z10: BK | AA10: PedT
A11: Gabriel Luce | B11: O | C11: O | D11: PedT | E11: TH | F11: AnUS | G11: TH | H11: SICU | I11: SICU | J11: NICU | K11: J | L11: T | M11: T | N11: BH | O11: V | P11: M | Q11: M | R11: BK | S11: BK | T11: V | U11: PedB | V11: TH | W11: BH | X11: TH | Y11: PSY | Z11: MICU | AA11: MICU
A12: Jude Luke | B12: O | C12: O | D12: MICU | E12: MICU | F12: PSY | G12: PedT | H12: PedB | I12: BH | J12: M | K12: M | L12: V | M12: NICU | N12: T | O12: T | P12: BK | Q12: J | R12: TH | S12: TH | T12: SICU | U12: SICU | V12: AnUS | W12: BK | X12: BH | Y12: TH | Z12: V | AA12: TH
A13: Liam Mcloughlin | B13: O | C13: O | D13: NICU | E13: BH | F13: TH | G13: BH | H13: J | I13: PedT | J13: BK | K13: V | L13: M | M13: M | N13: BK | O13: AnUS | P13: T | Q13: T | R13: SICU | S13: SICU | T13: TH | U13: PSY | V13: PedB | W13: V | X13: TH | Y13: TH | Z13: MICU | AA13: MICU
A14: Miray Mirham | B14: O | C14: O | D14: AnUS | E14: TH | F14: BH | G14: NICU | H14: M | I14: M | J14: TH | K14: BK | L14: TH | M14: V | N14: J | O14: PedB | P14: SICU | Q14: SICU | R14: T | S14: T | T14: PedT | U14: BH | V14: V | W14: PSY | X14: MICU | Y14: MICU | Z14: TH | AA14: BK
... A20: Samanta Torres Bertorelli | B20: O | C20: O | D20: TH | E20: PedB | F20: TH | G20: BK | H20: NICU | I20: TH | J20: T | K20: T | L20: M | M20: M | N20: PSY | O20: V | P20: J | Q20: BH | R20: MICU | S20: MICU | T20: TH | U20: BK | V20: PedT | W20: AnUS | X20: V | Y20: BH | Z20: SICU | AA20: SICU
B22: Key: Name and Location
B23: O: Orientation
B24: BH: Bellevue ED (BH)
B25: TH: Tisch ED (TH)
B26: BK: NYU Brooklyn ED
B27: PedB: Bellevue Pediatrics (BH)
B28: PedT: NYU Peds ED (TH)
B29: M: Medicine (BH)
B30: MICU: Medical ICU (BH/TH)
B31: SICU: Surgical ICU (BH)
B32: T: Trauma (BH)
B33: NICU: Neonatal ICU (TH)
... B37: V: Vacation

Sheet PGY2
B1: 1A | C1: 1B | D1: 2A | E1: 2B | F1: 3A | G1: 3B | H1: 4A | I1: 4B | J1: 5A | K1: 5B | L1: 6A | M1: 6B | N1: 7A | O1: 7B | P1: 8A | Q1: 8B | R1: 9A | S1: 9B | T1: 10A | U1: 10B | V1: 11A | W1: 11B | X1: 12A | Y1: 12B | Z1: 13A | AA1: 13B
B2: 44743 | C2: 45852 | D2: 45866 | E2: 45880 | F2: 45894 | G2: 45908 | H2: 45922 | I2: 45936 | J2: 45950 | K2: 45964 | L2: 45978 | M2: 45992 | N2: 46006 | O2: 46020 | P2: 45669 | Q2: 45683 | R2: 45697 | S2: 45711 | T2: 45725 | U2: 45739 | V2: 45753 | W2: 45767 | X2: 45781 | Y2: 45795 | Z2: 45809 | AA2: 45823
A3: Anas Maqsood | B3: BH/TH | C3: BK | D3: CCU | E3: CCU | F3: BH/TH | G3: V | H3: BK | I3: BH/TH | J3: PedB | K3: BH/TH | L3: BH/TH | M3: EMS | N3: BK | O3: AnUS | P3: BH/TH | Q3: Ob | R3: BH/TH | S3: PedT | T3: BH/TH | U3: V | V3: Ortho | W3: Ortho | X3: BH/TH | Y3: BH/TH | Z3: J | AA3: BH/TH
A4: Avery Tamakloe | B4: BH/TH | C4: BH/TH | D4: BH/TH | E4: BH/TH | F4: J | G4: BK | H4: BH/TH | I4: EMS | J4: CCU | K4: CCU | L4: BK | M4: AnUS | N4: BH/TH | O4: BH/TH | P4: V | Q4: BH/TH | R4: PedT | S4: BK | T4: Ortho | U4: Ortho | V4: BH/TH | W4: BH/TH | X4: BH/TH | Y4: V | Z4: PedB | AA4: Ob
A5: Christopher Connolly | B5: BH/TH | C5: BH/TH | D5: BH/TH | E5: BK | F5: Ortho | G5: Ortho | H5: BH/TH | I5: BH/TH | J5: EMS | K5: BK | L5: CCU | M5: CCU | N5: J | O5: Ob | P5: V | Q5: PedB | R5: BH/TH | S5: BH/TH | T5: BH/TH | U5: BH/TH | V5: AnUS | W5: BK | X5: BH/TH | Y5: PedT | Z5: V | AA5: BH/TH
A6: Dave Youssef | B6: PedB | C6: J | D6: Ortho | E6: Ortho | F6: BK | G6: BH/TH | H6: PedT | I6: BH/TH | J6: Ob | K6: BH/TH | L6: AnUS | M6: BH/TH | N6: V | O6: BH/TH | P6: BH/TH | Q6: BH/TH | R6: CCU | S6: CCU | T6: BK | U6: V | V6: BH/TH | W6: BH/TH | X6: EMS | Y6: BK | Z6: BH/TH | AA6: BH/TH
A7: Edom Girma | B7: BH/TH | C7: PedB | D7: BH/TH | E7: BK | F7: PedT | G7: J | H7: BH/TH | I7: BH/TH | J7: EMS | K7: BH/TH | L7: BK | M7: Ob | N7: BH/TH | O7: BH/TH | P7: Ortho | Q7: Ortho | R7: BH/TH | S7: AnUS | T7: BH/TH | U7: V | V7: BK | W7: BH/TH | X7: CCU | Y7: CCU | Z7: BH/TH | AA7: V
A8: Eilish Moogan | B8: BH/TH | C8: BH/TH | D8: BH/TH | E8: AnUS | F8: BK | G8: BH/TH | H8: CCU | I8: CCU | J8: BH/TH | K8: EMS | L8: J | M8: BH/TH | N8: V | O8: PedT | P8: PedB | Q8: BK | R8: BH/TH | S8: BH/TH | T8: Ortho | U8: Ortho | V8: V | W8: BH/TH | X8: Ob | Y8: BH/TH | Z8: BK | AA8: BH/TH
A9: Jacqueline Penn | B9: J | C9: BH/TH | D9: BH/TH | E9: BH/TH | F9: CCU | G9: CCU | H9: BK | I9: V | J9: BK | K9: EMS | L9: BH/TH | M9: BH/TH | N9: BH/TH | O9: BH/TH | P9: Ortho | Q9: Ortho | R9: BH/TH | S9: PedB | T9: Ob | U9: BH/TH | V9: BH/TH | W9: V | X9: PedT | Y9: BH/TH | Z9: AnUS | AA9: BK
A10: Jason Martinez | B10: BH/TH | C10: BK | D10: AnUS | E10: PedB | F10: BH/TH | G10: BH/TH | H10: BH/TH | I10: J | J10: CCU | K10: CCU | L10: BH/TH | M10: V | N10: BH/TH | O10: BK | P10: PedT | Q10: BH/TH | R10: BH/TH | S10: BH/TH | T10: EMS | U10: BH/TH | V10: V | W10: BK | X10: BH/TH | Y10: Ob | Z10: Ortho | AA10: Ortho
A11: JiMin Ko | B11: BH/TH | C11: V | D11: BH/TH | E11: BH/TH | F11: BH/TH | G11: BH/TH | H11: PedT | I11: BK | J11: Ortho | K11: Ortho | L11: PedB | M11: BK | N11: CCU | O11: CCU | P11: Ob | Q11: BH/TH | R11: EMS | S11: BH/TH | T11: BH/TH | U11: BH/TH | V11: V | W11: AnUS | X11: BK | Y11: BH/TH | Z11: BH/TH | AA11: J
A12: Lauren Chung | B12: BK | C12: BH/TH | D12: PedT | E12: BH/TH | F12: BH/TH | G12: Ob | H12: BH/TH | I12: V | J12: AnUS | K12: BK | L12: BH/TH | M12: BH/TH | N12: PedB | O12: BH/TH | P12: EMS | Q12: BH/TH | R12: J | S12: BH/TH | T12: CCU | U12: CCU | V12: BK | W12: V | X12: Ortho | Y12: Ortho | Z12: BH/TH | AA12: BH/TH
A13: Madison Polay | B13: PedT | C13: BH/TH | D13: BH/TH | E13: EMS | F13: V | G13: BH/TH | H13: BH/TH | I13: BH/TH | J13: BH/TH | K13: PedB | L13: BH/TH | M13: J | N13: Ob | O13: BH/TH | P13: CCU | Q13: CCU | R13: Ortho | S13: Ortho | T13: BK | U13: V | V13: BH/TH | W13: BH/TH | X13: BK | Y13: AnUS | Z13: BH/TH | AA13: BK
A14: Nicholas Friedman | B14: BH/TH | C14: PedT | D14: BK | E14: V | F14: BH/TH | G14: BH/TH | H14: Ortho | I14: Ortho | J14: BH/TH | K14: BH/TH | L14: CCU | M14: CCU | N14: BK | O14: J | P14: BH/TH | Q14: V | R14: PedB | S14: BH/TH | T14: BH/TH | U14: BH/TH | V14: BH/TH | W14: Ob | X14: AnUS | Y14: BK | Z14: EMS | AA14: NICU
... A20: Rachel Friend | B20: Ortho | C20: Ortho | D20: BH/TH | E20: BH/TH | F20: CCU | G20: CCU | H20: Ob | I20: V | J20: BH/TH | K20: BH/TH | L20: BH/TH | M20: PedT | N20: BH/TH | O20: BH/TH | P20: AnUS | Q20: BH/TH | R20: EMS | S20: BK | T20: PedB | U20: BK | V20: V | W20: BH/TH | X20: J | Y20: BK | Z20: BH/TH | AA20: BH/TH
B22: Key: Name and Location
B23: BH/TH: Bellevue and Tisch ED
B24: BK: NYU Brooklyn ED
B25: Peds: Bellevue Peds ED (PES)
B26: PedT: NYU Peds ED (TH)
B27: Ortho: Bellevue Ortho Consult (BH)
B28: AnUs: Anesthesia and Ultrasound (BH/TH)
B29: OB: Obstetrics Nights (TH)
B30: CCU: Cardiac Critical Care (BH)
B31: J: Jeopardy (Sick Call)
B32: EMS: Emergency Medical Services (FDNY)
B33: V: Vacation

Sheet PGY3
B1: 1A | C1: 1B | D1: 2A | E1: 2B | F1: 3A | G1: 3B | H1: 4A | I1: 4B | J1: 5A | K1: 5B | L1: 6A | M1: 6B | N1: 7A | O1: 7B | P1: 8A | Q1: 8B | R1: 9A | S1: 9B | T1: 10A | U1: 10B | V1: 11A | W1: 11B | X1: 12A | Y1: 12B | Z1: 13A | AA1: 13B
B2: 44743 | C2: 45852 | D2: 45866 | E2: 45880 | F2: 45894 | G2: 45908 | H2: 45922 | I2: 45936 | J2: 45950 | K2: 45964 | L2: 45978 | M2: 45992 | N2: 46006 | O2: 46020 | P2: 45669 | Q2: 45683 | R2: 45697 | S2: 45711 | T2: 45725 | U2: 45739 | V2: 45753 | W2: 45767 | X2: 45781 | Y2: 45795 | Z2: 45809 | AA2: 45823
A3: Amy Tan | B3: BKN | C3: ED | D3: Elec | E3: BKN | F3: ED | G3: ED | H3: PICU | I3: ED | J3: Tox-SC | K3: Tox-H | L3: CH | M3: ED | N3: BKN | O3: V | P3: ED | Q3: Hand | R3: ED | S3: ED | T3: ED | U3: Elec | V3: MICU | W3: MICU | X3: ED | Y3: V | Z3: ED | AA3: ED
A4: Brian Chastain | B4: BKN | C4: ED | D4: Elec | E4: ED | F4: ED | G4: BKN | H4: V | I4: ED | J4: ED | K4: ED | L4: PICU | M4: Elec | N4: ED | O4: ED | P4: Tox-H | Q4: Tox-SC | R4: CH | S4: ED | T4: V | U4: Hand | V4: ED | W4: ED | X4: MICU | Y4: MICU | Z4: ED | AA4: BKN
A5: Colin Baylen | B5: ED | C5: BKN | D5: Tox-H | E5: Tox-SC | F5: ED | G5: ED | H5: BKN | I5: ED | J5: V | K5: ED | L5: ED | M5: CH | N5: Elec | O5: ED | P5: Elec | Q5: ED | R5: ED | S5: ED | T5: MICU | U5: MICU | V5: ED | W5: Hand | X5: PICU | Y5: BKN | Z5: V | AA5: ED
A6: Courtney O'Connor | B6: ED | C6: BKN | D6: PICU | E6: Elec | F6: BKN | G6: ED | H6: MICU | I6: MICU | J6: ED | K6: CH | L6: ED | M6: V | N6: ED | O6: ED | P6: ED | Q6: ED | R6: Tox-SC | S6: Tox-H | T6: V | U6: ED | V6: ED | W6: BKN | X6: Elec | Y6: ED | Z6: Hand | AA6: ED
A7: Douglas Martin | B7: ED | C7: Elec | D7: ED | E7: PICU | F7: V | G7: CH | H7: ED | I7: BKN | J7: ED | K7: Elec | L7: ED | M7: ED | N7: ED | O7: ED | P7: MICU | Q7: MICU | R7: V | S7: BKN | T7: ED | U7: ED | V7: Tox-SC | W7: Tox-H | X7: ED | Y7: Hand | Z7: ED | AA7: BKN
A8: Elaine Jonas | B8: BKN | C8: ED | D8: ED | E8: Hand | F8: ED | G8: ED | H8: V | I8: BKN | J8: ED | K8: ED | L8: ED | M8: ED | N8: Tox-H | O8: Tox-SC | P8: Elec | Q8: ED | R8: MICU | S8: MICU | T8: V | U8: ED | V8: ED | W8: CH | X8: Elec | Y8: ED | Z8: BKN | AA8: PICU
A9: Jonathan (Jake) Rost | B9: BKN | C9: ED | D9: MICU | E9: MICU | F9: ED | G9: Elec | H9: V | I9: CH | J9: ED | K9: PICU | L9: ED | M9: BKN | N9: Elec | O9: Hand | P9: Tox-SC | Q9: Tox-H | R9: ED | S9: ED | T9: V | U9: ED | V9: ED | W9: ED | X9: ED | Y9: BKN | Z9: ED | AA9: ED
A10: Kayla Diedrick | B10: Elec | C10: PICU | D10: ED | E10: ED | F10: ED | G10: BKN | H10: ED | I10: ED | J10: Hand | K10: ED | L10: BKN | M10: ED | N10: Elec | O10: ED | P10: ED | Q10: ED | R10: V | S10: BKN | T10: Tox-H | U10: Tox-SC | V10: MICU | W10: MICU | X10: ED | Y10: CH | Z10: ED | AA10: V
A11: Mac Josh Reandelar | B11: Elec | C11: ED | D11: ED | E11: ED | F11: BKN | G11: PICU | H11: ED | I11: ED | J11: Tox-H | K11: Tox-SC | L11: ED | M11: V | N11: BKN | O11: ED | P11: ED | Q11: ED | R11: MICU | S11: MICU | T11: ED | U11: ED | V11: Hand | W11: V | X11: Elec | Y11: ED | Z11: BKN | AA11: CH
A12: Matthew Generoso | B12: ED | C12: BKN | D12: ED | E12: ED | F12: V | G12: Hand | H12: ED | I12: PICU | J12: CH | K12: ED | L12: BKN | M12: ED | N12: MICU | O12: MICU | P12: Elec | Q12: BKN | R12: ED | S12: ED | T12: ED | U12: ED | V12: Tox-H | W12: Tox-SC | X12: V | Y12: ED | Z12: Elec | AA12: ED
A13: Milos Tomovic | B13: ED | C13: ED | D13: ED | E13: ED | F13: V | G13: Elec | H13: CH | I13: ED | J13: BKN | K13: Hand | L13: ED | M13: BKN | N13: ED | O13: ED | P13: BKN | Q13: ED | R13: Elec | S13: PICU | T13: V | U13: ED | V13: ED | W13: ED | X13: MICU | Y13: MICU | Z13: Tox-H | AA13: Tox-SC
A14: Neya Vishwanath | B14: ED | C14: CH | D14: ED | E14: ED | F14: BKN | G14: ED | H14: V | I14: ED | J14: MICU | K14: MICU | L14: Tox-H | M14: Tox-SC | N14: Elec | O14: BKN | P14: ED | Q14: ED | R14: PICU | S14: Hand | T14: ED | U14: V | V14: ED | W14: ED | X14: BKN | Y14: ED | Z14: Elec | AA14: ED
... A21: Joonho Lee | B21: MICU | C21: MICU | D21: V | E21: ED | F21: ED | G21: BKN | H21: Tox-H | I21: Tox-SC | J21: ED | K21: ED | L21: ED | M21: Hand | N21: ED | O21: ED | P21: ED | Q21: ED | R21: V | S21: BKN | T21: ED | U21: Elec | V21: ED | W21: ED | X21: CH | Y21: ED | Z21: PICU | AA21: BKN
B23: BKN | C23: Brooklyn
B24: MICU | C24: Medical ICU
B25: Elec | C25: Elective
B26: PICU | C26: Peds ICU
B27: Hand | C27: Hand
B28: Tox-SC | C28: Tox/Sick Call
B29: Tox-H | C29: Tox Heavy
B30: ED | C30: BH/TH
B31: CH | C31: Cobble Hill
B32: V | C32: Vacation

Sheet PGY4
B1: 1A | C1: 1B | D1: 2A | E1: 2B | F1: 3A | G1: 3B | H1: 4A | I1: 4B | J1: 5A | K1: 5B | L1: 6A | M1: 6B | N1: 7A | O1: 7B | P1: 8A | Q1: 8B | R1: 9A | S1: 9B | T1: 10A | U1: 10B | V1: 11A | W1: 11B | X1: 12A | Y1: 12B | Z1: 13A | AA1: 13B | AB1: 1A
B2: 44743 | C2: 45852 | D2: 45866 | E2: 45880 | F2: 45894 | G2: 45908 | H2: 45922 | I2: 45936 | J2: 45950 | K2: 45964 | L2: 45978 | M2: 45992 | N2: 46006 | O2: 46020 | P2: 45669 | Q2: 45683 | R2: 45697 | S2: 45711 | T2: 45725 | U2: 45739 | V2: 45753 | W2: 45767 | X2: 45781 | Y2: 45795 | Z2: 45809 | AA2: 45823 | AB2: 7/1-7/7
A3: Annaliese Elam | B3: E-S | C3: ED | D3: BKN | E3: ED | F3: ED | G3: Elec | H3: BKN | I3: Elec | J3: ED | K3: ED | L3: ED | M3: ED | N3: V | O3: ED | P3: ED | Q3: Elec | R3: Elec | S3: ED | T3: ED | U3: ED | V3: ED | W3: ED | X3: BKN | Y3: V | Z3: ED | AA3: ED
A4: Christopher Pham | B4: ED | C4: V | D4: ED | E4: E-S | F4: ED | G4: ED | H4: ED | I4: Elec | J4: BKN | K4: ED | L4: BKN | M4: ED | N4: V | O4: ED | P4: ED | Q4: BKN | R4: ED | S4: ED | T4: ED | U4: ED | V4: Elec | W4: ED | X4: Elec | Y4: Elec | Z4: ED | AA4: ED
A5: Collins Mbachu | B5: V | C5: BKN | D5: ED | E5: ED | F5: ED | G5: Elec | H5: ED | I5: ED | J5: Elec | K5: ED | L5: ED | M5: ED | N5: ED | O5: Elec | P5: ED | Q5: ED | R5: ED | S5: ED | T5: BKN | U5: Elec | V5: ED | W5: BKN | X5: ED | Y5: E-S | Z5: ED | AA5: V
A6: Elie Nwefo | B6: ED | C6: ED | D6: BKN | E6: ED | F6: ED | G6: BKN | H6: ED | I6: ED | J6: BKN | K6: ED/V | L6: V | M6: V/Elec | N6: Elec | O6: Elec | P6: ED | Q6: ED | R6: ED | S6: Elec/ED | T6: ED | U6: ED | V6: E-S | W6: ED | X6: ED | Y6: ED | Z6: ED | AA6: ED
A7: Erica (Jacobs) Cohen | B7: ED | C7: E-S | D7: ED | E7: EMS | F7: ED | G7: BKN | H7: V | I7: ED | J7: ED | K7: ED | L7: V | M7: BKN | N7: ED | O7: ED | P7: ED | Q7: Elec | R7: ED | S7: ED | T7: ED | U7: ED | V7: Hand/Elec | W7: ED | X7: ED | Y7: ED | Z7: BKN | AA7: Elec | AB7: Elec
A8: John Altavilla | B8: Elec | C8: BKN | D8: Elec | E8: ED | F8: ED | G8: ED | H8: ED | I8: ED | J8: ED | K8: Elec | L8: ED | M8: ED | N8: V | O8: ED | P8: Elec | Q8: ED | R8: BKN | S8: E-S | T8: ED | U8: ED | V8: ED | W8: BKN | X8: V | Y8: ED | Z8: ED | AA8: ED
A9: Joonho Lee | B9: MICU | C9: MICU | D9: V | E9: ED | F9: ED | G9: BKN | H9: Tox-H | I9: Tox-SC | J9: ED | K9: ED | L9: ED | M9: Hand | N9: ED | O9: ED | P9: ED | Q9: ED | R9: V | S9: ED | T9: BKN | U9: Elec | V9: ED | W9: ED | X9: CH | Y9: ED | Z9: PICU | AA9: BKN
A10: Marina Gaeta Gazzola | B10: Elec | C10: ED | D10: ED | E10: ED | F10: Elec | G10: ED | H10: ED | I10: ED | J10: BKN | K10: E-S | L10: ED | M10: ED | N10: V | O10: ED | P10: ED | Q10: ED | R10: Elec | S10: ED | T10: ED | U10: Elec | V10: BKN | W10: V | X10: ED | Y10: BKN | Z10: ED | AA10: ED
A11: Mitchell Foster | B11: ED | C11: ED | D11: ED | E11: Elec | F11: BKN | G11: ED | H11: ED | I11: ED | J11: Elec | K11: BKN | L11: ED | M11: Elec | N11: V | O11: ED | P11: ED | Q11: ED | R11: ED | S11: ED | T11: BKN | U11: ED | V11: ED | W11: V | X11: ED | Y11: ED | Z11: ED | AA11: E-S
A12: Natalie Bertrand | B12: ED | C12: ED | D12: ED | E12: ED | F12: Elec | G12: ED | H12: ED | I12: Elec | J12: ED | K12: BKN | L12: V | M12: ED | N12: ED | O12: ED | P12: BKN | Q12: Elec | R12: ED | S12: ED | T12: ED | U12: E-S | V12: BKN | W12: Elec | X12: ED | Y12: V | Z12: ED | AA12: ED
A13: Nazanin Sarpoulaki | B13: ED | C13: V | D13: Elec | E13: ED | F13: ED | G13: ED | H13: Elec | I13: BKN | J13: ED | K13: ED | L13: ED | M13: BKN | N13: ED | O13: V | P13: BKN | Q13: ED | R13: Elec | S13: ED | T13: Elec | U13: ED | V13: ED | W13: ED | X13: ED | Y13: ED | Z13: E-S | AA13: ED
A14: Nicolas Gonzalez | B14: Elec | C14: ED | D14: ED | E14: BKN | F14: Elec | G14: ED | H14: ED | I14: E-S | J14: ED | K14: ED | L14: ED | M14: ED | N14: V | O14: ED | P14: V | Q14: ED | R14: ED | S14: Elec | T14: ED | U14: ED | V14: BKN | W14: Elec | X14: ED | Y14: ED | Z14: Elec | AA14: ED
A15: Noumi Chowdhury | B15: ED | C15: ED | D15: ED | E15: BKN | F15: E-S | G15: ED | H15: ED | I15: ED | J15: ED | K15: Elec | L15: V | M15: ED | N15: ED | O15: ED | P15: Elec | Q15: Elec | R15: ED | S15: BKN | T15: V | U15: ED | V15: ED | W15: ED | X15: ED | Y15: BKN | Z15: ED | AA15: Elec
A16: Philip Lin | B16: ED | C16: ED | D16: E-S | E16: V | F16: ED | G16: ED | H16: BKN | I16: ED | J16: ED | K16: ED | L16: ED | M16: Elec | N16: ED | O16: BKN | P16: ED | Q16: ED | R16: BKN | S16: Elec | T16: ED | U16: ED | V16: Elec | W16: ED | X16: ED | Y16: ED | Z16: Elec | AA16: V
A17: Sarah Fetterolf | B17: Elec | C17: ED | D17: ED | E17: ED | F17: ED | G17: ED | H17: V | I17: BKN | J17: ED | K17: ED | L17: Elec | M17: ED | N17: ED | O17: ED | P17: E-S | Q17: ED | R17: Elec | S17: BKN | T17: ED | U17: V | V17: ED | W17: BKN | X17: ED | Y17: ED | Z17: Elec | AA17: ED
A18: Somil Chugh | B18: ED | C18: ED | D18: ED | E18: Elec | F18: BKN | G18: ED | H18: ED | I18: ED | J18: Elec | K18: ED | L18: ED | M18: ED | N18: ED | O18: E-S | P18: ED | Q18: Elec | R18: ED | S18: ED | T18: BKN | U18: V | V18: ED | W18: ED | X18: BKN | Y18: Elec | Z18: ED | AA18: V
A19: Sophia Faude | B19: ED | C19: Elec | D19: ED | E19: ED | F19: Elec | G19: V | H19: ED | I19: BKN | J19: ED | K19: ED | L19: Elec | M19: ED | N19: ED | O19: BKN | P19: Elec | Q19: ED | R19: ED | S19: V | T19: ED | U19: ED | V19: ED | W19: ED | X19: E-S | Y19: ED | Z19: BKN | AA19: ED
A20: Vivian Chiu | B20: ED | C20: ED | D20: Elec | E20: ED | F20: ED | G20: E-S | H20: ED | I20: ED | J20: Elec | K20: BKN | L20: ED | M20: Elec | N20: ED | O20: V | P20: ED | Q20: BKN | R20: ED | S20: ED | T20: Elec | U20: BKN | V20: ED | W20: ED | X20: V | Y20: ED | Z20: ED | AA20: ED
B22: Elec | C22: Elective
B23: V | C23: Vacation
B24: ED | C24: BH/TH
B25: BKN | C25: Brooklyn
B26: E-S | C26: Elective/Sick Call

Sheet OSRs
A1: Off service rotator | B1: Amion ID
A2: Phillip Cohen (Med) | B2: PC
A3: Elizabeth Flagg (Med) | B3: EF
A4: Abhishek Bhattacharya (Med) | B4: ABh
A5: Tyler Warner (Ortho)
A6: Yonathan Daniel (Med) | B6: YD
A7: Jeremy Perrelle (Med) | B7: JPl
A8: Colby Smith (Med) | B8: CS
A9: Mariela Trejo (Med) | B9: MTr
A10: Geoffrey Cloud (Med) | B10: GC
A11: Daniel Grubman (Med) | B11: DG
A12: Katharine Martin (Med) | B12: KMa
A13: Carolyn Wilson (Med) | B13: CWi
A14: Nimi Patel (Psych) | B14: NP
